<?xml version="1.0" ?>
<robot name="new" xmlns:xacro="http://www.ros.org/wiki/xacro">

<xacro:include filename="$(find robot_arm2)/urdf/materials.xacro" />
<xacro:include filename="$(find robot_arm2)/urdf/New.trans" />
<xacro:include filename="$(find robot_arm2)/urdf/robot_arm2.ros2_control.xacro" />
<xacro:include filename="$(find robot_arm2)/urdf/robot_arm2.gazebo.xacro" />
<xacro:include filename="$(find robot_arm2)/urdf/coordinate_frames.xacro" />

<!-- World link to fix robot to ground -->
<link name="world"/>

<joint name="world_to_base" type="fixed">
  <parent link="world"/>
  <child link="base_link"/>
  <origin xyz="0 0 0" rpy="0 0 0"/>
</joint>

<xacro:include filename="$(find robot_arm2)/urdf/robot_arm2.gazebo.xacro" />
<link name="base_link">
  <inertial>
    <origin xyz="-0.0036121165905485014 -0.0038615409254074595 0.028804958902608237" rpy="0 0 0"/>
    <mass value="1.6847968268400857"/>
    <inertia ixx="0.003511" iyy="0.003304" izz="0.005332" ixy="1.1e-05" iyz="1.4e-05" ixz="-1.2e-05"/>
  </inertial>
  <visual>
    <origin xyz="0 0 0" rpy="0 0 0"/>
    <geometry>
      <mesh filename="package://robot_arm2/meshes/base_link.stl" scale="0.001 0.001 0.001"/>
    </geometry>
    <material name="steel_satin"/>
  </visual>
  <collision>
    <origin xyz="0 0 0" rpy="0 0 0"/>
    <geometry>
      <mesh filename="package://robot_arm2/meshes/base_link.stl" scale="0.001 0.001 0.001"/>
    </geometry>
  </collision>
</link>

<link name="Link1_1">
  <inertial>
    <origin xyz="0.0005318788464895104 -0.011019648052413528 0.035354468678565745" rpy="0 0 0"/>
    <mass value="1.6326910488895168"/>
    <inertia ixx="0.002276" iyy="0.002562" izz="0.002335" ixy="-2.3e-05" iyz="0.000395" ixz="3.1e-05"/>
  </inertial>
  <visual>
    <origin xyz="0.003394 0.003955 -0.068502" rpy="0 0 0"/>
    <geometry>
      <mesh filename="package://robot_arm2/meshes/Link1_1.stl" scale="0.001 0.001 0.001"/>
    </geometry>
    <material name="steel_satin"/>
  </visual>
  <collision>
    <origin xyz="0.003394 0.003955 -0.068502" rpy="0 0 0"/>
    <geometry>
      <mesh filename="package://robot_arm2/meshes/Link1_1.stl" scale="0.001 0.001 0.001"/>
    </geometry>
  </collision>
</link>

<link name="Link2_1">
  <inertial>
    <origin xyz="-0.045474223805009165 0.0008084159626991563 0.06293544579356647" rpy="0 0 0"/>
    <mass value="1.7295947703464407"/>
    <inertia ixx="0.003195" iyy="0.004256" izz="0.00182" ixy="-1.8e-05" iyz="-6.5e-05" ixz="-0.000207"/>
  </inertial>
  <visual>
    <origin xyz="-0.038427 0.023939 -0.122024" rpy="0 0 0"/>
    <geometry>
      <mesh filename="package://robot_arm2/meshes/Link2_1.stl" scale="0.001 0.001 0.001"/>
    </geometry>
    <material name="steel_satin"/>
  </visual>
  <collision>
    <origin xyz="-0.038427 0.023939 -0.122024" rpy="0 0 0"/>
    <geometry>
      <mesh filename="package://robot_arm2/meshes/Link2_1.stl" scale="0.001 0.001 0.001"/>
    </geometry>
  </collision>
</link>

<link name="Link4_1">
  <inertial>
    <origin xyz="-0.0011726538890279989 -0.031329933048232 0.03834400352353268" rpy="0 0 0"/>
    <mass value="1.1900466863549668"/>
    <inertia ixx="0.001996" iyy="0.001998" izz="0.000833" ixy="9e-06" iyz="-5.3e-05" ixz="-5.3e-05"/>
  </inertial>
  <visual>
    <origin xyz="0.005255 -0.007589 -0.300911" rpy="0 0 0"/>
    <geometry>
      <mesh filename="package://robot_arm2/meshes/Link4_1.stl" scale="0.001 0.001 0.001"/>
    </geometry>
    <material name="steel_satin"/>
  </visual>
  <collision>
    <origin xyz="0.005255 -0.007589 -0.300911" rpy="0 0 0"/>
    <geometry>
      <mesh filename="package://robot_arm2/meshes/Link4_1.stl" scale="0.001 0.001 0.001"/>
    </geometry>
  </collision>
</link>

<link name="Link5_1">
  <inertial>
    <origin xyz="0.02795372196178319 0.005978945251756934 0.02478004965456676" rpy="0 0 0"/>
    <mass value="0.7433695485084677"/>
    <inertia ixx="0.000632" iyy="0.000871" izz="0.000826" ixy="-1.6e-05" iyz="-0.000137" ixz="-3.6e-05"/>
  </inertial>
  <visual>
    <origin xyz="0.037834 0.025511 -0.378125" rpy="0 0 0"/>
    <geometry>
      <mesh filename="package://robot_arm2/meshes/Link5_1.stl" scale="0.001 0.001 0.001"/>
    </geometry>
    <material name="steel_satin"/>
  </visual>
  <collision>
    <origin xyz="0.037834 0.025511 -0.378125" rpy="0 0 0"/>
    <geometry>
      <mesh filename="package://robot_arm2/meshes/Link5_1.stl" scale="0.001 0.001 0.001"/>
    </geometry>
  </collision>
</link>

<link name="Link6_1">
  <inertial>
    <origin xyz="2.034758205745127e-05 -0.015764532464094774 -0.0017226102756212613" rpy="0 0 0"/>
    <mass value="0.07963447481314566"/>
    <inertia ixx="1.2e-05" iyy="1.1e-05" izz="9e-06" ixy="0.0" iyz="-0.0" ixz="-0.0"/>
  </inertial>
  <visual>
    <origin xyz="0.006234 0.010211 -0.441925" rpy="0 0 0"/>
    <geometry>
      <mesh filename="package://robot_arm2/meshes/Link6_1.stl" scale="0.001 0.001 0.001"/>
    </geometry>
    <material name="steel_satin"/>
  </visual>
  <collision>
    <origin xyz="0.006234 0.010211 -0.441925" rpy="0 0 0"/>
    <geometry>
      <mesh filename="package://robot_arm2/meshes/Link6_1.stl" scale="0.001 0.001 0.001"/>
    </geometry>
  </collision>
</link>

<link name="Link3_1">
  <inertial>
    <origin xyz="0.030097938259797705 0.003047532311787133 0.030962449646626644" rpy="0 0 0"/>
    <mass value="0.9069734682837254"/>
    <inertia ixx="0.001116" iyy="0.001117" izz="0.001148" ixy="-9e-06" iyz="-5.2e-05" ixz="-5.4e-05"/>
  </inertial>
  <visual>
    <origin xyz="0.037459 0.023946 -0.238747" rpy="0 0 0"/>
    <geometry>
      <mesh filename="package://robot_arm2/meshes/Link3_1.stl" scale="0.001 0.001 0.001"/>
    </geometry>
    <material name="steel_satin"/>
  </visual>
  <collision>
    <origin xyz="0.037459 0.023946 -0.238747" rpy="0 0 0"/>
    <geometry>
      <mesh filename="package://robot_arm2/meshes/Link3_1.stl" scale="0.001 0.001 0.001"/>
    </geometry>
  </collision>
</link>

<link name="End-effector_1">
  <inertial>
    <origin xyz="-3.511222701427924e-07 -4.131916280653014e-08 2.989811020981392e-08" rpy="0 0 0"/>
    <mass value="3.288200310757317e-05"/>
    <inertia ixx="0.0" iyy="0.0" izz="0.0" ixy="-0.0" iyz="0.0" ixz="0.0"/>
  </inertial>
  <visual>
    <origin xyz="0.006155 0.026302 -0.488369" rpy="0 0 0"/>
    <geometry>
      <mesh filename="package://robot_arm2/meshes/End-effector_1.stl" scale="0.001 0.001 0.001"/>
    </geometry>
    <material name="steel_satin"/>
  </visual>
  <collision>
    <origin xyz="0.006155 0.026302 -0.488369" rpy="0 0 0"/>
    <geometry>
      <mesh filename="package://robot_arm2/meshes/End-effector_1.stl" scale="0.001 0.001 0.001"/>
    </geometry>
  </collision>
</link>

<joint name="Joint 1" type="continuous">
  <origin xyz="-0.003394 -0.003955 0.068502" rpy="0 0 0"/>
  <parent link="base_link"/>
  <child link="Link1_1"/>
  <axis xyz="0.0 0.0 1.0"/>
  <limit effort="100" velocity="100"/>
</joint>

<joint name="Joint 2" type="continuous">
  <origin xyz="0.041821 -0.019984 0.053522" rpy="0 0 0"/>
  <parent link="Link1_1"/>
  <child link="Link2_1"/>
  <axis xyz="-1.0 0.0 0.0"/>
  <limit effort="100" velocity="100"/>
</joint>

<joint name="Joint 4" type="continuous">
  <origin xyz="0.032204 0.031535 0.062164" rpy="0 0 0"/>
  <parent link="Link3_1"/>
  <child link="Link4_1"/>
  <axis xyz="0.0 -1.0 0.0"/>
  <limit effort="100" velocity="100"/>
</joint>

<joint name="Joint 5" type="continuous">
  <origin xyz="-0.032579 -0.0331 0.077214" rpy="0 0 0"/>
  <parent link="Link4_1"/>
  <child link="Link5_1"/>
  <axis xyz="-1.0 0.0 0.0"/>
  <limit effort="100" velocity="100"/>
</joint>

<joint name="Joint 6" type="continuous">
  <origin xyz="0.0316 0.0153 0.0638" rpy="0 0 0"/>
  <parent link="Link5_1"/>
  <child link="Link6_1"/>
  <axis xyz="0.0 -1.0 0.0"/>
  <limit effort="100" velocity="100"/>
</joint>

<joint name="Joint 3" type="continuous">
  <origin xyz="-0.075886 -7e-06 0.116723" rpy="0 0 0"/>
  <parent link="Link2_1"/>
  <child link="Link3_1"/>
  <axis xyz="-1.0 0.0 0.0"/>
  <limit effort="100" velocity="100"/>
</joint>

<joint name="Rigid 7" type="fixed">
  <origin xyz="7.9e-05 -0.016091 0.046444" rpy="0 0 0"/>
  <parent link="Link6_1"/>
  <child link="End-effector_1"/>
</joint>

</robot>
